Workbook

Sheet CAPEX
A1: Data collection: individual plants
B3: PTES
B4: plant | C4: year of op. Start | D4: country | E4: capacity [m3] | F4: CAPEX [currency] | G4: currency of ref. | H4: monetary value [CHF] | I4: CAPEX per m3 [CHF/m3] | J4: source 1 | K4: source 2 | L4: source 3
B5: Martsal I | C5: 2003 | D5: DK | E5: 10000 | F5: 230000 | G5: EUR | H5: 1.1804946 | I5: =F5/E5*H5 -> 27.151376 | J5: https://ens.dk/en/analyses-and-statistics/technology-data-energy-storage
B6: Ottrupgaard | C6: 1996 | D6: DK | E6: 1500 | F6: 230000 | G6: DK | H6: 1.8604485 | I6: =F6/E6*H6 -> 285.26877 | J6: https://doi.org/10.1016/j.rser.2021.110732 | K6: https://ens.dk/en/analyses-and-statistics/technology-data-energy-storage
B7: Eggenstein | C7: 2008 | D7: DE | E7: 3000 | F7: 508608.15 | G7: EUR | H7: 1.1804946 | I7: =F7/E7*H7 -> 200.1364 | J7: https://doi.org/10.1016/j.rser.2021.110732 | K7: https://www.saisonalspeicher.de/ | L7: https://www.solar-district-heating.eu/en/plant-database/#legend
B8: Steinfurt | C8: 1999 | D8: DE | E8: 1500 | F8: 730849.57 | G8: EUR | H8: 1.1804946 | I8: =F8/E8*H8 -> 575.17599 | J8: https://doi.org/10.1016/j.rser.2021.110732 | K8: https://www.saisonalspeicher.de/ | L8: http://www.aee-now.at/cms/fileadmin/downloads/projekte/store4grid/store4grid_stand_der_technik.pdf
B9: Chemnitz | C9: 2000 | D9: DE | E9: 5360 | F9: 840368.76 | G9: EUR | H9: 1.1804946 | I9: =F9/E9*H9 -> 185.08411 | J9: https://doi.org/10.1016/j.rser.2021.110732 | K9: https://www.saisonalspeicher.de/
B10: Osijek | C10: 2013 | D10: HR | E10: 30350 | F10: 1764678.4 | G10: EUR | H10: 1.1804946 | I10: =F10/E10*H10 -> 68.638992 | J10: https://doi.org/10.1016/j.rser.2021.110732
B11: Dronninglund | C11: 2014 | D11: DK | E11: 60000 | F11: 2378447 | G11: EUR | H11: 1.1804946 | I11: =F11/E11*H11 -> 46.795731 | J11: https://doi.org/10.1016/j.rser.2021.110732 | K11: https://ens.dk/en/analyses-and-statistics/technology-data-energy-storage | L11: https://www.solar-district-heating.eu/en/plant-database/#legend
B12: Martsal II | C12: 2013 | D12: DK | E12: 75000 | F12: 2744814.7 | G12: EUR | H12: 1.1804946 | I12: =F12/E12*H12 -> 43.203187 | J12: https://doi.org/10.1016/j.rser.2021.110732 | K12: https://ens.dk/en/analyses-and-statistics/technology-data-energy-storage
B13: Bracht | C13: 2025 | D13: DE | E13: 26600 | F13: 3458000 | G13: EUR | H13: 0.95432497 | I13: =F13/E13*H13 -> 124.06225 | J13: https://www.solarwaerme-bracht.de/technik/ | K13: https://www.mega-monheim.de/unternehmen/aktuelles/deutschlands-erster-erdbeckenspeicher-hat-es-schwer?
B14: Toflund | C14: 2017 | D14: DK | E14: 85000 | F14: 4110000 | G14: EUR | H14: 1.1960428 | I14: =F14/E14*H14 -> 57.832188 | J14: https://ens.dk/en/analyses-and-statistics/technology-data-energy-storage | K14: https://www.solar-district-heating.eu/en/plant-database/#legend
B15: Gram | C15: 2015 | D15: DK | E15: 125000 | F15: 4320000 | G15: EUR | H15: 1.1492425 | I15: =F15/E15*H15 -> 39.717822 | J15: https://ens.dk/en/analyses-and-statistics/technology-data-energy-storage | K15: https://www.solar-district-heating.eu/en/plant-database/#legend
B16: Vojens | C16: 2015 | D16: DK | E16: 210000 | F16: 5010000 | G16: EUR | H16: 1.1492425 | I16: =F16/E16*H16 -> 27.417643 | J16: https://ens.dk/en/analyses-and-statistics/technology-data-energy-storage | K16: https://www.solar-district-heating.eu/en/plant-database/#legend
B17: Høje Taastrup | C17: 2022 | D17: DK | E17: 70000 | F17: 6000000 | G17: EUR | H17: 1.0393778 | I17: =F17/E17*H17 -> 89.089527 | J17: https://ens.dk/en/analyses-and-statistics/technology-data-energy-storage
B18: Stuttgart | D18: DE | E18: 800 | F18: =E18*I18 -> 250573.42 | G18: EUR | H18: 1.2784358 | I18: =245*H18 -> 313.21678 | J18: https://doi.org/10.1016/j.rser.2021.110732 | L18: value from: https://www.verenum.ch/Dokumente/2012_Mangold_Speicher.pdf
B19: Meldorf | C19: 2022 | D19: DE | E19: 43000 | F19: 7740000 | G19: EUR | H19: 0.95432497 | I19: =F19/E19*H19 -> 171.7785 | J19: https://meldorfwaerme.de/?page_id=30 | K19: https://www.mega-monheim.de/unternehmen/aktuelles/deutschlands-erster-erdbeckenspeicher-hat-es-schwer?
B23: TTES
B24: plant | C24: year of op. Start | D24: country | E24: capacity [m3] | F24: CAPEX [currency] | G24: currency of ref. | H24: monetary value [CHF] | I24: CAPEX per m3 [CHF/m3] | J24: source 1 | K24: source 2 | L24: source 3
B25: Marseille | C25: 2017 | D25: FR | E25: 0.3 | F25: 936.37 | G25: EUR | H25: 1.1804946 | I25: =F25/E25*H25 -> 3684.5992 | J25: https://doi.org/10.1016/j.rser.2021.110732
B26: Marseille | C26: 2017 | D26: FR | E26: 3 | F26: 14565.77 | G26: EUR | H26: 1.1804946 | I26: =F26/E26*H26 -> 5731.6044 | J26: https://doi.org/10.1016/j.rser.2021.110732
B27: Copenhagen | C27: 2017 | D27: DK | E27: 0.255 | F27: 1387.05 | G27: EUR | H27: 1.1804946 | I27: =F27/E27*H27 -> 6421.1964 | J27: https://doi.org/10.1016/j.rser.2021.110732
B28: Panningen | C28: 2021 | D28: NL | E28: 121100 | F28: 19400000 | G28: EUR | H28: 1.1804946 | I28: =F28/E28*H28 -> 189.11309 | J28: https://doi.org/10.1016/j.rser.2021.110732
B29: Marseille | C29: 2018 | D29: FR | E29: 200 | F29: 21625.91 | G29: EUR | H29: 1.1804946 | I29: =F29/E29*H29 -> 127.64635 | J29: https://doi.org/10.1016/j.rser.2021.110732
B30: Jincheon | C30: 2017 | D30: KR | E30: 2000 | F30: 280372.91 | G30: EUR | H30: 1.1804946 | I30: =F30/E30*H30 -> 165.48936 | J30: https://doi.org/10.1016/j.rser.2021.110732
B31: Hannover-Kronsberg | C31: 2000 | D31: DE | E31: 2750 | F31: 887897.49 | G31: EUR | H31: 1.1804946 | I31: 306.8246 | J31: https://www.verenum.ch/Dokumente/2012_Mangold_Speicher.pdf | K31: https://doi.org/10.1016/j.rser.2021.110732 | L31: https://www.solar-district-heating.eu/en/plant-database/#legend
B32: Hamburg I | C32: 1996 | D32: DE | E32: 4500 | F32: 960460 | G32: DE | H32: 1.9044045 | I32: 268.47153 | J32: https://www.verenum.ch/Dokumente/2012_Mangold_Speicher.pdf | K32: https://www.saisonalspeicher.de/
B33: Munich | C33: 2007 | D33: DE | E33: 5700 | F33: 1038209 | G33: EUR | H33: 1.1804946 | I33: 191.76538 | J33: https://www.verenum.ch/Dokumente/2012_Mangold_Speicher.pdf | K33: https://doi.org/10.1016/j.rser.2021.110732 | L33: https://www.solar-district-heating.eu/en/plant-database/#legend
B34: Friedrichshafen | C34: 1996 | D34: DE | E34: 12000 | F34: 1351642 | G34: DE | H34: 1.9044045 | I34: 147.02012 | J34: https://www.verenum.ch/Dokumente/2012_Mangold_Speicher.pdf | K34: https://doi.org/10.1016/j.rser.2021.110732 | L34: https://www.saisonalspeicher.de/
B35: Ilmenau | D35: DE | E35: 300 | G35: EUR | H35: 1.2784358 | I35: 600.86484 | J35: https://www.verenum.ch/Dokumente/2012_Mangold_Speicher.pdf
B36: Rottweil | D36: DE | E36: 700 | G36: EUR | H36: 1.2784358 | I36: 575.29613 | J36: https://www.verenum.ch/Dokumente/2012_Mangold_Speicher.pdf
B37: Crailsheim | D37: DE | E37: 600 | G37: EUR | H37: 1.2784358 | I37: 613.6492 | J37: https://www.verenum.ch/Dokumente/2012_Mangold_Speicher.pdf
B38: Mannheim | C38: 2013 | D38: DE | E38: 43000 | F38: 8400000 | G38: EUR | H38: 1.0393778 | I38: =F38/E38*H38 -> 203.04125 | J38: https://doi.org/10.1016/j.rser.2025.116202
B39: data points extracted from other cost curves | E39: 200 | H39: 1.1960428 | I39: 645.86312 | J39: https://www.euroheat.org/dhc/knowledge-hub/large-storage-systems-for-dhc-networks
E40: 400 | H40: 1.1960428 | I40: 478.41712 | J40: https://www.euroheat.org/dhc/knowledge-hub/large-storage-systems-for-dhc-networks
E41: 1000 | H41: 1.1960428 | I41: 281.07006 | J41: https://www.euroheat.org/dhc/knowledge-hub/large-storage-systems-for-dhc-networks
E42: 1200 | H42: 1.1960428 | I42: 275.08985 | J42: https://www.euroheat.org/dhc/knowledge-hub/large-storage-systems-for-dhc-networks
E43: 1500 | H43: 1.1960428 | I43: 346.85241 | J43: https://www.euroheat.org/dhc/knowledge-hub/large-storage-systems-for-dhc-networks
E44: 1500 | H44: 1.1960428 | I44: 239.20856 | J44: https://www.euroheat.org/dhc/knowledge-hub/large-storage-systems-for-dhc-networks
...

Sheet OPEX
A1: Source name | B1: storage type | C1: OPEX [(currency)/kWh] or [% of CAPEX] | D1: source link
A2: Forum Energiespeicher Schweiz | B2: ATES | C2: 4% / 7.29% | D2: https://speicher.aeesuisse.ch/wp-content/uploads/sites/15/2021/09/FESS_Fokusstudie_Saisonale_Waermespeicher.pdf
A3: IEA factsheet | B3: ATES | C3: 2% / 2.5% | D3: https://iea-es.org/task-39/presentations-publications/
A4: Forum Energiespeicher Schweiz | B4: BTES | C4: 0.005 | D4: https://speicher.aeesuisse.ch/wp-content/uploads/sites/15/2021/09/FESS_Fokusstudie_Saisonale_Waermespeicher.pdf
A5: IEA factsheet | B5: BTES | C5: 0.05 | D5: https://iea-es.org/task-39/presentations-publications/
A6: Danish Energy Agency | B6: PTES | C6: 0.0024 | D6: https://ens.dk/en/analyses-and-statistics/technology-data-energy-storage
A7: Danish Energy Agency | B7: TTES | C7: 0.002867 | D7: https://ens.dk/en/analyses-and-statistics/technology-data-energy-storage
A8: Forum Energiespeicher Schweiz | B8: PTES | C8: 0.0071 | D8: https://speicher.aeesuisse.ch/wp-content/uploads/sites/15/2021/09/FESS_Fokusstudie_Saisonale_Waermespeicher.pdf
A9: IEA factsheet | B9: PTES | C9: 0.02 | D9: https://iea-es.org/task-39/presentations-publications/
A10: IEA factsheet | B10: TTES | C10: 0.0275 | D10: https://iea-es.org/task-39/presentations-publications/
A11: Forum Energiespeicher Schweiz | B11: TTES | C11: 0.005 | D11: https://speicher.aeesuisse.ch/wp-content/uploads/sites/15/2021/09/FESS_Fokusstudie_Saisonale_Waermespeicher.pdf
A14: temperature [°C] | B14: PTES (DEA) | C14: PTES (FESS) | D14: PTES (IEA) | E14: TTES (FESS) | F14: TTES (IEA) | G14: TTES (DEA) | H14: BTES (FESS) | I14: BTES (IEA) | J14: ATES (FESS) | K14: ATES (IEA) | M14: PTES avg | N14: TTES avg | O14: BTES avg | P14: ATES avg
A15: 10 | B15: 0.0024134791 | C15: 0.0071482609 | D15: 0.02 | E15: 0.0050002335 | F15: 0.0275 | G15: 0.002867 | H15: 0.05 | I15: 0.05 | J15: 0.03999 | K15: 0.025 | M15: =AVERAGE(OPEX!$B15:$D15) -> 0.0098539133 | N15: =AVERAGE(OPEX!$E15:$G15) -> 0.011789078 | O15: =AVERAGE(OPEX!$H15:$I15) -> 0.05 | P15: =AVERAGE(OPEX!$J15:$K15) -> 0.032495
A16: 20 | B16: 0.0024134791 | C16: 0.0071482609 | D16: 0.02 | E16: 0.0050002335 | F16: 0.0275 | G16: 0.002867 | H16: 0.05 | I16: 0.05 | J16: 0.03999 | K16: 0.025 | M16: =AVERAGE(OPEX!$B16:$D16) -> 0.0098539133 | N16: =AVERAGE(OPEX!$E16:$G16) -> 0.011789078 | O16: =AVERAGE(OPEX!$H16:$I16) -> 0.05 | P16: =AVERAGE(OPEX!$J16:$K16) -> 0.032495
A17: 30 | B17: 0.0024134791 | C17: 0.0071482609 | D17: 0.02 | E17: 0.0050002335 | F17: 0.0275 | G17: 0.002867 | H17: 0.05 | I17: 0.05 | J17: 0.072912 | K17: 0.025 | M17: =AVERAGE(OPEX!$B17:$D17) -> 0.0098539133 | N17: =AVERAGE(OPEX!$E17:$G17) -> 0.011789078 | O17: =AVERAGE(OPEX!$H17:$I17) -> 0.05 | P17: =AVERAGE(OPEX!$J17:$K17) -> 0.048956
A18: 40 | B18: 0.0024134791 | C18: 0.0071482609 | D18: 0.02 | E18: 0.0050002335 | F18: 0.0275 | G18: 0.002867 | H18: 0.05 | I18: 0.05 | J18: 0.072912 | K18: 0.025 | M18: =AVERAGE(OPEX!$B18:$D18) -> 0.0098539133 | N18: =AVERAGE(OPEX!$E18:$G18) -> 0.011789078 | O18: =AVERAGE(OPEX!$H18:$I18) -> 0.05 | P18: =AVERAGE(OPEX!$J18:$K18) -> 0.048956
A19: 50 | B19: 0.0024134791 | C19: 0.0071482609 | D19: 0.02 | E19: 0.0050002335 | F19: 0.0275 | G19: 0.002867 | H19: 0.05 | I19: 0.05 | J19: 0.072912 | K19: 0.025 | M19: =AVERAGE(OPEX!$B19:$D19) -> 0.0098539133 | N19: =AVERAGE(OPEX!$E19:$G19) -> 0.011789078 | O19: =AVERAGE(OPEX!$H19:$I19) -> 0.05 | P19: =AVERAGE(OPEX!$J19:$K19) -> 0.048956
A20: 60 | B20: 0.0024134791 | C20: 0.0071482609 | D20: 0.02 | E20: 0.0050002335 | F20: 0.0275 | G20: 0.002867 | H20: 0.05 | I20: 0.05 | J20: 0.072912 | K20: 0.025 | M20: =AVERAGE(OPEX!$B20:$D20) -> 0.0098539133 | N20: =AVERAGE(OPEX!$E20:$G20) -> 0.011789078 | O20: =AVERAGE(OPEX!$H20:$I20) -> 0.05 | P20: =AVERAGE(OPEX!$J20:$K20) -> 0.048956
A21: 70 | B21: 0.0024134791 | C21: 0.0071482609 | D21: 0.02 | E21: 0.0050002335 | F21: 0.0275 | G21: 0.002867 | H21: 0.05 | I21: 0.05 | J21: 0.072912 | K21: 0.02 | M21: =AVERAGE(OPEX!$B21:$D21) -> 0.0098539133 | N21: =AVERAGE(OPEX!$E21:$G21) -> 0.011789078 | O21: =AVERAGE(OPEX!$H21:$I21) -> 0.05 | P21: =AVERAGE(OPEX!$J21:$K21) -> 0.046456
A22: 80 | B22: 0.0024134791 | C22: 0.0071482609 | D22: 0.02 | E22: 0.0050002335 | F22: 0.0275 | G22: 0.002867 | H22: 0.05 | I22: 0.05 | J22: 0.072912 | K22: 0.02 | M22: =AVERAGE(OPEX!$B22:$D22) -> 0.0098539133 | N22: =AVERAGE(OPEX!$E22:$G22) -> 0.011789078 | O22: =AVERAGE(OPEX!$H22:$I22) -> 0.05 | P22: =AVERAGE(OPEX!$J22:$K22) -> 0.046456
A23: 90 | B23: 0.0024134791 | C23: 0.0071482609 | D23: 0.02 | E23: 0.0050002335 | F23: 0.0275 | G23: 0.002867 | H23: 0.05 | I23: 0.05 | J23: 0.072912 | K23: 0.02 | M23: =AVERAGE(OPEX!$B23:$D23) -> 0.0098539133 | N23: =AVERAGE(OPEX!$E23:$G23) -> 0.011789078 | O23: =AVERAGE(OPEX!$H23:$I23) -> 0.05 | P23: =AVERAGE(OPEX!$J23:$K23) -> 0.046456
A24: 100 | B24: 0.0024134791 | C24: 0.0071482609 | D24: 0.02 | E24: 0.0050002335 | F24: 0.0275 | G24: 0.002867 | H24: 0.05 | I24: 0.05 | J24: 0.072912 | K24: 0.02 | M24: =AVERAGE(OPEX!$B24:$D24) -> 0.0098539133 | N24: =AVERAGE(OPEX!$E24:$G24) -> 0.011789078 | O24: =AVERAGE(OPEX!$H24:$I24) -> 0.05 | P24: =AVERAGE(OPEX!$J24:$K24) -> 0.046456
M26: =AVERAGE(M15:M24) -> 0.0098539133 | N26: =AVERAGE(N15:N24) -> 0.011789078 | O26: =AVERAGE(O15:O24) -> 0.05 | P26: =AVERAGE(P15:P24) -> 0.0446638
L27: SD: | M27: =SUMPRODUCT((B15:D24 - $M$26)^2) / (COUNT(B15:D24) - 1) -> 5.7111618e-05 | N27: =SUMPRODUCT((E15:G24 - $N$26)^2) / (COUNT(E15:G24) - 1) -> 0.00012845688 | O27: =SUMPRODUCT((H15:I24 - $O$26)^2) / (COUNT(H15:I24) - 1) -> 5.0682367e-35 | P27: =SUMPRODUCT((J15:K24 - $P$26)^2) / (COUNT(J15:K24) - 1) -> 0.00058845145

Sheet inflation & currencies
B1: inflation w.r.t. 1970 | C1: [national currency/CHF] | AO1: EURO & EU [currency/CHF] | AQ1: Non-OECD economies [national currency/CHF]
A2: year | B2: CH infl. | C2: AU | D2: AT | E2: BE | F2: CA | G2: CHF | H2: CL | I2: CO | J2: CR | K2: CZ | L2: DK | M2: EE | N2: FI | O2: FR | P2: DE | Q2: GR | R2: HU | S2: IS | T2: IE | U2: IL | V2: IT | W2: JP | X2: KR | Y2: LV | Z2: LT | AA2: LU | AB2: MX | AC2: NL | AD2: NZ | AE2: NO | AF2: PL | AG2: PT | AH2: SK | AI2: SI | AJ2: ES | AK2: SE | AL2: TR | AM2: GB | AN2: US | AO2: EUR | AP2: EU | AQ2: Brazil | AR2: China (People’s Republic of) | AS2: India | AT2: Indonesia | AU2: Russia | AV2: South Africa
A3: 1970 | C3: 0.20417727 | D3: 0.43208674 | E3: 0.2834397 | F3: 0.23879046 | G3: 1 | H3: 0.0025789236 | I3: 4.2177859 | J3: 1.5149956 | L3: 1.7150894 | N3: 0.16153495 | O3: 0.1936292 | P3: 0.4279327 | Q3: 0.020133111 | R3: 13.720715 | S3: 0.20123715 | T3: 0.12098422 | U3: 8.0037328e-05 | V3: 0.073814144 | W3: 82.324289 | X3: 71.017467 | AA3: 0.2834397 | AB3: 0.0028584823 | AC3: 0.37564673 | AD3: 0.20417727 | AE3: 1.6334191 | AF3: 9.1471432e-05 | AG3: 0.032793514 | AJ3: 0.096207017 | AK3: 1.1830023 | AL3: 2.5905853e-06 | AM3: 0.095282818 | AN3: 0.22867858 | AR3: 0.56296296 | AS3: 1.7150894 | AT3: 82.972212 | AV3: 0.16334191
A4: 1971 | C4: 0.21352235 | D4: 0.43924462 | E4: 0.29417842 | F4: 0.24427822 | G4: 1 | H4: 0.0029533319 | I4: 4.821973 | J4: 1.6028222 | L4: 1.7964683 | N4: 0.17024513 | O4: 0.20432729 | P4: 0.43380868 | Q4: 0.021297579 | R4: 14.471148 | S4: 0.2128764 | T4: 0.12621661 | U4: 9.1722112e-05 | V4: 0.077503662 | W4: 84.830688 | X4: 83.976717 | AA4: 0.29417842 | AB4: 0.0030238125 | AC4: 0.38607592 | AD4: 0.21302328 | AE4: 1.7068588 | AF4: 9.4181681e-05 | AG4: 0.034219865 | AJ4: 0.10099899 | AK4: 1.2399821 | AL4: 3.596321e-06 | AM4: 0.099403661 | AN4: 0.241905 | AR4: 0.59552389 | AS4: 1.8123366 | AT4: 94.796523 | AV4: 0.17301455
A5: 1972 | C5: 0.21959751 | D5: 0.43983944 | E5: 0.28568253 | F5: 0.25938667 | G5: 1 | H5: 0.0054553185 | I5: 5.7253824 | J5: 1.7372521 | L5: 1.8195435 | N5: 0.18259166 | O5: 0.20135782 | P5: 0.42687088 | Q5: 0.023052161 | R5: 14.468809 | S5: 0.23109342 | T5: 0.13311279 | U5: 0.00010944025 | V5: 0.078865406 | W5: 79.380114 | X5: 102.87207 | AA5: 0.28568253 | AB5: 0.0032728999 | AC5: 0.3813334 | AD5: 0.2190692 | AE5: 1.7250112 | AF5: 9.6353996e-05 | AG5: 0.035332035 | AJ5: 0.10114001 | AK5: 1.2469508 | AL5: 3.7049159e-06 | AM5: 0.10483484 | AN5: 0.26183151 | AR5: 0.58782914 | AS5: 1.9884711 | AT5: 108.66008 | AV5: 0.20127649
A6: 1973 | C6: 0.22248057 | D6: 0.44960791 | E6: 0.30529323 | F6: 0.31600089 | G6: 1 | H6: 0.022636866 | I6: 7.4479962 | J6: 2.1001922 | L6: 1.9114751 | N6: 0.20306728 | O6: 0.21448898 | P6: 0.43176956 | Q6: 0.02747103 | R6: 15.471976 | S6: 0.28479909 | T6: 0.16375908 | U6: 0.0001325407 | V6: 0.095136833 | W6: 85.850229 | X6: 125.85866 | AA6: 0.30529323 | AB6: 0.0039496399 | AC6: 0.40083162 | AD6: 0.2328123 | AE6: 1.8218442 | AF6: 0.00010585076 | AG6: 0.038637465 | AJ6: 0.11063779 | AK6: 1.3799305 | AL6: 4.4710095e-06 | AM6: 0.12897076 | AN6: 0.31597241 | AR6: 0.62860041 | AS6: 2.4462705 | AT6: 131.12855 | AV6: 0.21927193
A7: 1974 | C7: 0.23383935 | D7: 0.45596608 | E7: 0.32410253 | F7: 0.32827642 | G7: 1 | H7: 0.19898507 | I7: 8.7477273 | J7: 2.6617437 | L7: 2.0457833 | N7: 0.21303992 | O7: 0.24610946 | P7: 0.44410357 | Q7: 0.029551722 | R7: 15.692674 | S7: 0.33549271 | T7: 0.18230717 | U7: 0.00014941794 | V7: 0.11273787 | W7: 98.038936 | X7: 135.7632 | AA7: 0.32410253 | AB7: 0.0041956764 | AC7: 0.40947727 | AD7: 0.24012842 | AE7: 1.8594305 | AF7: 0.00011143744 | AG7: 0.042539364 | AJ7: 0.11637253 | AK7: 1.490115 | AL7: 4.6746944e-06 | AM7: 0.14357857 | AN7: 0.33565495 | AR7: 0.6582553 | AS7: 2.7193432 | AT7: 139.2968 | AV7: 0.22806982
A8: 1975 | C8: 0.29592693 | D8: 0.49034702 | E8: 0.3532063 | F8: 0.39405177 | G8: 1 | H8: 1.902316 | I8: 11.981443 | J8: 3.320054 | L8: 2.2260826 | N8: 0.23968981 | O8: 0.25323482 | P8: 0.48732626 | Q8: 0.036439671 | R8: 17.034699 | S8: 0.59542088 | T8: 0.22235989 | U8: 0.00024546508 | V8: 0.13062048 | W8: 114.97672 | X8: 187.50363 | AA8: 0.3532063 | AB8: 0.0048425525 | AC8: 0.44458753 | AD8: 0.32243931 | AE8: 2.0249391 | AF8: 0.00012861819 | AG8: 0.049377214 | AJ8: 0.13366317 | AK8: 1.6085765 | AL8: 5.5949237e-06 | AM8: 0.17512265 | AN8: 0.3874042 | AR8: 0.72050339 | AS8: 3.2448557 | AT8: 160.77274 | AV8: 0.28648841
A9: 1976 | C9: 0.32736055 | D9: 0.52156533 | E9: 0.38285371 | F9: 0.39446786 | G9: 1 | H9: 5.2224152 | I9: 13.879989 | J9: 3.4284914 | L9: 2.4183566 | N9: 0.26001656 | O9: 0.29291962 | P9: 0.51504701 | Q9: 0.042873448 | R9: 16.632491 | S9: 0.72879113 | T9: 0.28268921 | U9: 0.00031706831 | V9: 0.17197071 | W9: 118.638 | X9: 193.62775 | AA9: 0.38285371 | AB9: 0.0061712245 | AC9: 0.47997616 | AD9: 0.40201314 | AE9: 2.1829196 | AF9: 0.00013281904 | AG9: 0.060321459 | AJ9: 0.16086091 | AK9: 1.7426064 | AL9: 6.4221538e-06 | AM9: 0.22263584 | AN9: 0.40005734 | AR9: 0.77667746 | AS9: 3.5846789 | AT9: 166.0238 | AV9: 0.34787595
A10: 1977 | C10: 0.37520933 | D10: 0.49970684 | E10: 0.36967311 | F10: 0.44245082 | G10: 1 | H10: 8.9601037 | I10: 15.300097 | J10: 3.5655964 | L10: 2.4976614 | N10: 0.28196055 | O10: 0.31112173 | P10: 0.49398841 | Q10: 0.044979689 | R10: 17.041949 | S10: 0.82740974 | T10: 0.30284906 | U10: 0.00043458911 | V10: 0.189603 | W10: 111.71509 | X10: 201.3709 | AA10: 0.36967311 | AB10: 0.0093915672 | AC10: 0.46335698 | AD10: 0.42866692 | AE10: 2.2148719 | AF10: 0.00013813045 | AG10: 0.079435255 | AJ10: 0.18994594 | AK10: 1.864612 | AL10: 7.4899367e-06 | AM10: 0.23851302 | AN10: 0.41605559 | AR10: 0.77295779 | AS10: 3.6357334 | AT10: 172.66307 | AV10: 0.36178747
A11: 1978 | B11: 1.008 | C11: 0.48861691 | D11: 0.59022143 | E11: 0.43660931 | F11: 0.63794364 | G11: 1 | H11: 17.704357 | I11: 21.864907 | J11: 4.7929979 | L11: 3.084199 | N11: 0.38729087 | O11: 0.38479197 | P11: 0.57437321 | Q11: 0.060310611 | R11: 21.202919 | S11: 1.5162586 | T11: 0.37033835 | U11: 0.00097511901 | V11: 0.2451297 | W11: 117.69504 | X11: 270.68973 | AA11: 0.43660931 | AB11: 0.012733202 | AC11: 0.54909261 | AD11: 0.53938004 | AE11: 2.9318662 | AF11: 0.00032493953 | AG11: 0.12257015 | AJ11: 0.25770499 | AK11: 2.527076 | AL11: 1.358044e-05 | AM11: 0.29166515 | AN11: 0.5592763 | AR11: 0.94159166 | AS11: 4.5820614 | AT11: 247.22552 | AV11: 0.48632721
A12: 1979 | B12: 1.044 | C12: 0.53805705 | D12: 0.58425423 | E12: 0.43710822 | F12: 0.70452089 | G12: 1 | H12: 22.400477 | I12: 25.589519 | J12: 5.1541897 | L12: 3.164058 | N12: 0.39402068 | O12: 0.3900715 | P12: 0.56361597 | Q12: 0.065372655 | R12: 21.397405 | S12: 2.1206153 | T12: 0.37311493 | U12: 0.0015279959 | V12: 0.25807289 | W12: 131.7957 | X12: 291.08842 | AA12: 0.43710822 | AB12: 0.013715668 | AC12: 0.54746235 | AD12: 0.58849329 | AE12: 3.0456429 | AF12: 0.0019967222 | AG12: 0.14676463 | AJ12: 0.24263145 | AK12: 2.5783478 | AL12: 1.8690704e-05 | AM12: 0.28398031 | AN12: 0.60142236 | AR12: 0.93517506 | AS12: 4.8870324 | AT12: 374.71951 | AV12: 0.50641122
A13: 1980 | B13: 1.086 | C13: 0.52410334 | D13: 0.56110071 | E13: 0.43258243 | F13: 0.69775082 | G13: 1 | H13: 23.27374 | I13: 28.213939 | J13: 5.1142552 | L13: 3.363319 | N13: 0.37438197 | O13: 0.38442535 | P13: 0.55460619 | Q13: 0.074635309 | R13: 19.414049 | S13: 2.8630529 | T13: 0.36874677 | U13: 0.0030579854 | V13: 0.26395895 | W13: 135.31044 | X13: 362.66256 | AA13: 0.43258243 | AB13: 0.013696303 | AC13: 0.53838009 | AD13: 0.61268419 | AE13: 2.9475446 | AF13: 0.0026386851 | AG13: 0.1490169 | AJ13: 0.25716719 | AK13: 2.524052 | AL13: 4.5376682e-05 | AM13: 0.25678395 | AN13: 0.59676256 | AR13: 0.8941807 | AS13: 4.692311 | AT13: 374.16655 | AV13: 0.46477882
A14: 1981 | B14: 1.157 | C14: 0.44302827 | D14: 0.58925953 | E14: 0.4685829 | F14: 0.61036437 | G14: 1 | H14: 19.854991 | I14: 27.740561 | J14: 11.079764 | L14: 3.6265225 | N14: 0.3694927 | O14: 0.42179163 | P14: 0.58827774 | Q14: 0.082783723 | R14: 17.469486 | S14: 3.6778485 | T14: 0.4016236 | U14: 0.0058193323 | V14: 0.29888895 | W14: 112.27531 | X14: 346.71311 | AA14: 0.4685829 | AB14: 0.01248044 | AC14: 0.57644251 | AD14: 0.58689061 | AE14: 2.921997 | AF14: 0.0026041857 | AG14: 0.15629035 | AJ14: 0.28248326 | AK14: 2.5778099 | AL14: 5.6621639e-05 | AM14: 0.25335036 | AN14: 0.50910233 | AR14: 0.86778613 | AS14: 4.4080741 | AT14: 321.62879 | AV14: 0.44677748
A15: 1982 | B15: 1.222 | C15: 0.48558093 | D15: 0.61062863 | E15: 0.55787515 | F15: 0.60766887 | G15: 1 | H15: 25.0746 | I15: 31.5651 | J15: 18.424433 | L15: 4.1040951 | N15: 0.39932319 | O15: 0.49348496 | P15: 0.61109782 | Q15: 0.096562015 | R15: 18.042162 | S15: 6.083675 | T15: 0.44063427 | U15: 0.011952568 | V15: 0.34404853 | W15: 122.68125 | X15: 360.13225 | AA15: 0.55787515 | AB15: 0.027780325 | AC15: 0.59680965 | AD15: 0.65636839 | AE15: 3.1788961 | AF15: 0.0041779644 | AG15: 0.19525006 | AJ15: 0.32521057 | AK15: 3.0944618 | AL15: 8.0064729e-05 | AM15: 0.28195532 | AN15: 0.49254411 | AR15: 0.93216026 | AS15: 4.6570696 | AT15: 325.7789 | AV15: 0.5348122
A16: 1983 | B16: 1.258 | C16: 0.52879471 | D16: 0.6218953 | E16: 0.60382819 | F16: 0.58710274 | G16: 1 | H16: 37.533595 | I16: 37.566545 | J16: 19.576652 | L16: 4.3565386 | N16: 0.44628754 | O16: 0.55349215 | P16: 0.62190193 | Q16: 0.12311813 | R16: 20.327904 | S16: 11.834726 | T16: 0.48673713 | U16: 0.026779751 | V16: 0.37368593 | W16: 113.14704 | X16: 369.55502 | AA16: 0.60382819 | AB16: 0.057210804 | AC16: 0.61698811 | AD16: 0.71304065 | AE16: 3.475881 | AF16: 0.0043613064 | AG16: 0.26323496 | AJ16: 0.41065888 | AK16: 3.6524969 | AL16: 0.00010740442 | AM16: 0.31428302 | AN16: 0.47638519 | AR16: 0.94118231 | AS16: 4.8109656 | AT16: 433.1603 | AV16: 0.53074074
A17: 1984 | B17: 1.295 | C17: 0.48496712 | D17: 0.6188565 | E17: 0.60962507 | F17: 0.55116602 | G17: 1 | H17: 41.910967 | I17: 42.906846 | J17: 18.952632 | L17: 4.4076542 | N17: 0.43018964 | O17: 0.56699862 | P17: 0.61927786 | Q17: 0.14078054 | R17: 20.446248 | S17: 13.488516 | T17: 0.49853582 | U17: 0.12478689 | V17: 0.38617738 | W17: 101.08703 | X17: 343.01253 | AA17: 0.60962507 | AB17: 0.071425618 | AC17: 0.61967372 | AD17: 0.75073627 | AE17: 3.473429 | AF17: 0.0048193728 | AG17: 0.31076183 | AJ17: 0.4112014 | AK17: 3.5203893 | AL17: 0.00015605415 | AM17: 0.31996085 | AN17: 0.42558926 | AR17: 0.98738482 | AS17: 4.8357935 | AT17: 436.63111 | AV17: 0.62786227
A18: 1985 | B18: 1.339 | C18: 0.5827522 | D18: 0.61192027 | E18: 0.59905059 | F18: 0.55573379 | G18: 1 | H18: 65.466755 | I18: 57.91796 | J18: 20.533489 | L18: 4.3125163 | N18: 0.42424022 | O18: 0.55747621 | P18: 0.61259653 | Q18: 0.16496453 | R18: 20.397578 | S18: 16.892778 | T18: 0.48865376 | U18: 0.47976775 | V18: 0.4013402 | W18: 97.079242 | X18: 354.08048 | AA18: 0.59905059 | AB18: 0.10454152 | AC18: 0.61339395 | AD18: 0.82347154 | AE18: 3.4988995 | AF18: 0.0059883672 | AG18: 0.34590223 | AJ18: 0.41592736 | AK18: 3.5016228 | AL18: 0.00021243652 | AM18: 0.3171373 | AN18: 0.4069797 | AR18: 1.1951603 | AS18: 5.0338302 | AT18: 451.98352 | AV18: 0.90702549
A19: 1986 | B19: 1.349 | C19: 0.83159726 | D19: 0.61676334 | E19: 0.61558599 | F19: 0.77239323 | G19: 1 | H19: 107.24788 | I19: 107.98768 | J19: 31.122004 | L19: 4.4977023 | N19: 0.47396974 | O19: 0.58695096 | P19: 0.61718356 | Q19: 0.2283614 | R19: 25.477639 | S19: 22.849395 | T19: 0.52452588 | U19: 0.82707648 | V19: 0.42800154 | W19: 93.67851 | X19: 489.99259 | AA19: 0.61558599 | AB19: 0.34007833 | AC19: 0.61802356 | AD19: 1.0635072 | AE19: 4.1106638 | AF19: 0.0097440126 | AG19: 0.41476939 | AJ19: 0.46789699 | AK19: 3.9599296 | AL19: 0.00037495442 | AM19: 0.37922676 | AN19: 0.55589012 | AR19: 1.9193728 | AS19: 7.0102376 | AT19: 712.96243 | AV19: 1.2702265
A20: 1987 | B20: 1.369 | C20: 0.95774409 | D20: 0.61612892 | E20: 0.62063635 | F20: 0.88921003 | G20: 1 | H20: 147.13512 | I20: 162.69315 | J20: 42.098009 | L20: 4.5871479 | N20: 0.49576522 | O20: 0.61449282 | P20: 0.61628011 | Q20: 0.26652868 | R20: 31.498662 | S20: 25.937097 | T20: 0.5729833 | U20: 1.069374 | V20: 0.44887878 | W20: 96.994574 | X20: 551.61532 | AA20: 0.62063635 | AB20: 0.92421553 | AC20: 0.6164349 | AD20: 1.1363803 | AE20: 4.518165 | AF20: 0.017776555 | AG20: 0.47124628 | AJ20: 0.49766891 | AK20: 4.2519294 | AL20: 0.00057485177 | AM20: 0.41036073 | AN20: 0.67060461 | AR20: 2.4960574 | AS20: 8.6920416 | AT20: 1102.3723 | AV20: 1.3653733
A21: 1988 | B21: 1.395 | C21: 0.87467254 | D21: 0.61323032 | E21: 0.62288196 | F21: 0.84104479 | G21: 1 | H21: 167.43775 | I21: 204.45113 | J21: 51.803959 | L21: 4.6002358 | N21: 0.48076407 | O21: 0.62060405 | P21: 0.61364285 | Q21: 0.28450654 | R21: 34.451724 | S21: 29.395191 | T21: 0.56963151 | U21: 1.09269 | V21: 0.45939623 | W21: 87.577166 | X21: 499.87243 | AA21: 0.62288196 | AB21: 1.5534101 | AC21: 0.6129532 | AD21: 1.0431223 | AE21: 4.4536208 | AF21: 0.029422937 | AG21: 0.4906985 | AJ21: 0.47843912 | AK21: 4.1872138 | AL21: 0.00097201246 | AM21: 0.38417971 | AN21: 0.68338687 | AR21: 2.5436343 | AS21: 9.510752 | AT21: 1151.9881 | AV21: 1.5536578
A22: 1989 | B22: 1.439 | C22: 0.77301629 | D22: 0.58774702 | E22: 0.59709317 | F22: 0.7237325 | G22: 1 | H22: 163.1824 | I22: 233.85343 | J22: 49.821482 | L22: 4.468527 | N22: 0.44117591 | O22: 0.59455435 | P22: 0.58758809 | Q22: 0.2913608 | R22: 36.105776 | S22: 34.868219 | T22: 0.54761388 | U22: 1.1714575 | V22: 0.43316599 | W22: 84.334194 | X22: 410.44414 | AA22: 0.59709317 | AB22: 1.5046365 | AC22: 0.58825968 | AD22: 1.0221424 | AE22: 4.220548 | AF22: 0.087973725 | AG22: 0.48009441 | AJ22: 0.4349002 | AK22: 3.9408138 | AL22: 0.0012969294 | AM22: 0.3735946 | AN22: 0.61127497 | AR22: 2.3015165 | AS22: 9.918242 | AT22: 1081.9929 | AV22: 1.6031771
A23: 1990 | B23: 1.516 | C23: 0.9221819 | D23: 0.59480478 | E23: 0.59633844 | F23: 0.83991407 | G23: 1 | H23: 219.48782 | I23: 361.55706 | J23: 65.924301 | K23: 15.221447 | L23: 4.4548977 | N23: 0.46291871 | O23: 0.59757538 | P23: 0.59468479 | Q23: 0.33487273 | R23: 45.499397 | S23: 41.956179 | T23: 0.55261435 | U23: 1.4513644 | V23: 0.44542645 | W23: 104.23038 | X23: 509.49256 | AA23: 0.59633844 | AB23: 2.0246786 | AC23: 0.59482586 | AD23: 1.2066323 | AE23: 4.5061398 | AF23: 0.68386733 | AG23: 0.51186397 | AJ23: 0.44101177 | AK23: 4.2607022 | AL23: 0.0018778577 | AM23: 0.40540891 | AN23: 0.71986035 | AR23: 3.443242 | AS23: 12.600076 | AT23: 1326.5682 | AV23: 1.8625097
A24: 1991 | B24: 1.605 | C24: 0.89523242 | D24: 0.59172028 | E24: 0.59031933 | F24: 0.79897664 | G24: 1 | H24: 243.5271 | I24: 437.34738 | J24: 85.37875 | K24: 19.470127 | L24: 4.4605966 | N24: 0.47430434 | O24: 0.59981879 | P24: 0.59171207 | Q24: 0.37301317 | R24: 52.117028 | S24: 41.141342 | T24: 0.55013227 | U24: 1.5893456 | V24: 0.44681104 | W24: 93.938249 | X24: 511.39012 | AA24: 0.59031933 | AB24: 2.1049146 | AC24: 0.59164761 | AD24: 1.2088733 | AE24: 4.5209067 | AF24: 0.73752579 | AG24: 0.50256441 | AI24: 0.08023239 | AJ24: 0.43551243 | AK24: 4.2172258 | AL24: 0.002909233 | AM24: 0.39541048 | AN24: 0.69735412 | AR24: 3.7122891 | AS24: 15.85953 | AT24: 1360.0619 | AV24: 1.9256144
A25: 1992 | B25: 1.67 | C25: 0.96830506 | D25: 0.56792461 | E25: 0.56674363 | F25: 0.85955565 | G25: 1 | H25: 257.83751 | I25: 483.84082 | J25: 95.651102 | K25: 20.174677 | L25: 4.2924581 | N25: 0.53575445 | O25: 0.57390592 | P25: 0.56780583 | Q25: 0.39782267 | R25: 56.170788 | S25: 40.922474 | T25: 0.5306797 | U25: 1.7487209 | V25: 0.45262139 | W25: 90.065199 | X25: 555.1562 | Y25: 0.74518845 | Z25: 0.36510965 | AA25: 0.56674363 | AB25: 2.2008662 | AC25: 0.56744903 | AD25: 1.3239706 | AE25: 4.4193001 | AF25: 0.96901264 | AG25: 0.47884908 | AI25: 0.2412176 | AJ25: 0.43756412 | AK25: 4.1414859 | AL25: 0.0048871666 | AM25: 0.40518186 | AN25: 0.71112712 | AR25: 3.9215757 | AS25: 18.431052 | AT25: 1443.5318 | AV25: 2.0281446
A26: 1993 | B26: 1.725 | C26: 0.99522429 | D26: 0.57209944 | E26: 0.58041126 | F26: 0.87308699 | G26: 1 | H26: 273.5255 | I26: 532.1723 | J26: 96.216881 | K26: 19.729632 | L26: 4.3881064 | M26: 0.57192624 | N26: 0.65019468 | O26: 0.58428811 | P26: 0.57208986 | Q26: 0.45531442 | R26: 62.217208 | S26: 45.751502 | T26: 0.58197045 | U26: 1.9153028 | V26: 0.55002804 | W26: 75.254826 | X26: 543.13027 | Y26: 0.65031262 | Z26: 0.85145744 | AA26: 0.58041126 | AB26: 2.1085419 | AC26: 0.57038362 | AD26: 1.2523636 | AE26: 4.801062 | AF26: 1.2259585 | AG26: 0.54281192 | AH26: 0.69122329 | AI26: 0.31980555 | AJ26: 0.51762445 | AK26: 5.2675547 | AL26: 0.0074340176 | AM26: 0.45123784 | AN26: 0.67676551 | AQ26: 0.02590429 | AR26: 3.8994947 | AS26: 20.636808 | AT26: 1412.4799 | AU26: 0.6711258 | AV26: 2.2114948
A27: 1994 | B27: 1.74 | C27: 1.0000427 | D27: 0.60690279 | E27: 0.6063972 | F27: 0.99852375 | G27: 1 | H27: 307.21574 | I27: 604.33175 | J27: 114.84063 | K27: 21.046458 | L27: 4.6505714 | M27: 0.6070752 | N27: 0.64234595 | O27: 0.61885534 | P27: 0.60665792 | Q27: 0.52056086 | R27: 76.888963 | S27: 51.140427 | T27: 0.62074082 | U27: 2.2015586 | V27: 0.60887834 | W27: 74.730106 | X27: 587.68449 | Y27: 0.58233301 | Z27: 0.84232094 | AA27: 0.6063972 | AB27: 2.4677452 | AC27: 0.60384755 | AD27: 1.2331147 | AE27: 5.1602127 | AF27: 1.6613944 | AG27: 0.60537619 | AH27: 0.77772862 | AI27: 0.39300398 | AJ27: 0.58865829 | AK27: 5.6415971 | AL27: 0.021648635 | AM27: 0.47775842 | AN27: 0.7311585 | AQ27: 0.485989 | AR27: 6.301667 | AS27: 22.939179 | AT27: 1579.8534 | AU27: 1.6017855 | AV27: 2.5961964
A28: 1995 | B28: 1.771 | C28: 1.1408606 | D28: 0.61959406 | E28: 0.61802079 | F28: 1.1606606 | G28: 1 | H28: 335.54645 | I28: 772.02436 | J28: 151.9948 | K28: 22.445124 | L28: 4.7378543 | M28: 0.61966188 | N28: 0.62109071 | O28: 0.64352342 | P28: 0.61967706 | Q28: 0.57495055 | R28: 106.28727 | S28: 54.708967 | T28: 0.66976599 | U28: 2.5466133 | V28: 0.71145514 | W28: 79.545059 | X28: 652.2404 | Y28: 0.634844 | Z28: 0.97971271 | AA28: 0.61802079 | AB28: 5.4288308 | AC28: 0.6161883 | AD28: 1.2887242 | AE28: 5.3575661 | AF28: 2.0507793 | AG28: 0.63740453 | AH28: 0.8341061 | AI28: 0.4182509 | AJ28: 0.6337552 | AK28: 6.0325195 | AL28: 0.038770618 | AM28: 0.53588553 | AN28: 0.84568801 | AO28: 0.64654553 | AP28: 0.64654553 | AQ28: 0.7760597 | AR28: 7.062693 | AS28: 27.42319 | AT28: 1901.6208 | AU28: 3.8556185 | AV28: 3.0673823
A29: 1996 | B29: 1.785 | C29: 1.0338616 | D29: 0.62245058 | E29: 0.62096251 | F29: 1.1031639 | G29: 1 | H29: 333.54638 | I29: 838.68456 | J29: 168.03195 | K29: 21.961729 | L29: 4.691444 | M29: 0.62246133 | N29: 0.62505938 | O29: 0.63094666 | P29: 0.62246973 | Q29: 0.57153005 | R29: 123.49954 | S29: 53.802154 | T29: 0.64208406 | U29: 2.5822202 | V29: 0.64470806 | W29: 88.008233 | X29: 650.85032 | Y29: 0.6340132 | Z29: 0.93727403 | AA29: 0.62096251 | AB29: 6.1483713 | AC29: 0.61894855 | AD29: 1.1770516 | AE29: 5.2182493 | AF29: 2.181293 | AG29: 0.62245786 | AH29: 0.82322804 | AI29: 0.45700702 | AJ29: 0.61589425 | AK29: 5.4254867 | AL29: 0.06586103 | AM29: 0.51857044 | AN29: 0.80905494 | AO29: 0.63717656 | AP29: 0.63717656 | AQ29: 0.81318112 | AR29: 6.7266244 | AS29: 28.667384 | AT29: 1895.0464 | AU29: 4.1430355 | AV29: 3.4784097
A30: 1997 | B30: 1.795 | C30: 0.92838724 | D30: 0.61111374 | E30: 0.6110411 | F30: 0.95403163 | G30: 1 | H30: 288.90745 | I30: 786.26531 | J30: 160.267 | K30: 21.841207 | L30: 4.5506803 | M30: 0.61131254 | N30: 0.60161866 | O30: 0.61309877 | P30: 0.61090128 | Q30: 0.55215101 | R30: 128.70362 | S30: 48.855288 | T30: 0.57711485 | U30: 2.3767107 | V30: 0.60605566 | W30: 83.366513 | X30: 654.50411 | Y30: 0.56953272 | Z30: 0.79822924 | AA30: 0.6110411 | AB30: 5.4560682 | AC30: 0.61010133 | AD30: 1.0421056 | AE30: 4.8737958 | AF30: 2.2595352 | AG30: 0.60252688 | AH30: 0.76885737 | AI30: 0.45914826 | AJ30: 0.60632264 | AK30: 5.2606824 | AL30: 0.10463977 | AM30: 0.42088531 | AN30: 0.68903148 | AO30: 0.6075901 | AP30: 0.6075901 | AQ30: 0.74277019 | AR30: 5.7119446 | AS30: 25.020997 | AT30: 2004.6544 | AU30: 3.9859323 | AV30: 3.1750306
A31: 1998 | B31: 1.795 | C31: 1.097954 | D31: 0.62050868 | E31: 0.62064529 | F31: 1.0232388 | G31: 1 | H31: 317.48053 | I31: 983.86748 | J31: 177.42227 | K31: 22.26574 | L31: 4.6218548 | M31: 0.62044895 | N31: 0.61994696 | O31: 0.62033874 | P31: 0.62056525 | Q31: 0.59820813 | R31: 147.88226 | S31: 48.943083 | T31: 0.61504486 | U31: 2.6210789 | V31: 0.61847707 | W31: 90.291143 | X31: 967.83726 | Y31: 0.57887262 | Z31: 0.79905466 | AA31: 0.62064529 | AB31: 6.3015298 | AC31: 0.6208929 | AD31: 1.2886136 | AE31: 5.2041856 | AF31: 2.3971362 | AG31: 0.61963658 | AH31: 0.80667984 | AI31: 0.47817577 | AJ31: 0.6193101 | AK31: 5.4833737 | AL31: 0.17983298 | AM31: 0.41648369 | AN31: 0.68974398 | AO31: 0.61524407 | AP31: 0.61524407 | AQ31: 0.80045938 | AR31: 5.7103617 | AS31: 28.458399 | AT31: 6906.8358 | AU31: 6.6940228 | AV31: 3.8131007
A32: 1999 | B32: 1.809 | C32: 1.0318176 | D32: 0.62462467 | E32: 0.62462467 | F32: 0.98904895 | G32: 1 | H32: 338.69785 | I32: 1169.4438 | J32: 190.18323 | K32: 23.013105 | L32: 4.6441546 | M32: 0.62448186 | N32: 0.62462467 | O32: 0.62462467 | P32: 0.62462467 | Q32: 0.5971301 | R32: 157.87042 | S32: 48.154347 | T32: 0.62462467 | U32: 2.7558519 | V32: 0.62462467 | W32: 75.828929 | X32: 791.82186 | Y32: 0.55428178 | Z32: 0.77121207 | AA32: 0.62462467 | AB32: 6.3644547 | AC32: 0.62462467 | AD32: 1.2579354 | AE32: 5.1919886 | AF32: 2.6409447 | AG32: 0.62462467 | AH32: 0.91401655 | AI32: 0.50494749 | AJ32: 0.62462467 | AK32: 5.5003833 | AL32: 0.27878809 | AM32: 0.41144678 | AN32: 0.66571026 | AO32: 0.62462467 | AP32: 0.62462467 | AQ32: 1.2075537 | AR32: 5.510916 | AS32: 28.662441 | AT32: 5229.254 | AU32: 16.38972 | AV32: 4.0671463
A33: 2000 | B33: 1.838 | C33: 1.021307 | D33: 0.64109299 | E33: 0.64109299 | F33: 0.87953382 | G33: 1 | H33: 319.50137 | I33: 1236.3014 | J33: 182.48396 | K33: 22.854953 | L33: 4.7862037 | M33: 0.64215197 | N33: 0.64109299 | O33: 0.64109299 | P33: 0.64109299 | Q33: 0.63495335 | R33: 167.08436 | S33: 46.550194 | T33: 0.64109299 | U33: 2.4142768 | V33: 0.64109299 | W33: 63.810271 | X33: 669.31197 | Y33: 0.51098415 | Z33: 0.68596099 | AA33: 0.64109299 | AB33: 5.5988396 | AC33: 0.64109299 | AD33: 1.3033478 | AE33: 5.2117599 | AF33: 2.5734046 | AG33: 0.64109299 | AH33: 0.90481356 | AI33: 0.55015632 | AJ33: 0.64109299 | AK33: 5.425162 | AL33: 0.37020533 | AM33: 0.39135137 | AN33: 0.59212153 | AO33: 0.64109299 | AP33: 0.64109299 | AQ33: 1.0832408 | AR33: 4.9018805 | AS33: 26.610892 | AT33: 4986.7143 | AU33: 16.655885 | AV33: 4.1092218
A34: 2001 | B34: 1.856 | C34: 1.1456656 | D34: 0.66160415 | E34: 0.66160415 | F34: 0.91776854 | G34: 1 | H34: 376.23411 | I34: 1362.8069 | J34: 194.87314 | K34: 22.537918 | L34: 4.9317039 | M34: 0.66191185 | N34: 0.66160415 | O34: 0.66160415 | P34: 0.66160415 | Q34: 0.66160415 | R34: 169.76028 | S34: 57.729164 | T34: 0.66160415 | U34: 2.4920672 | V34: 0.66160415 | W34: 72.012247 | X34: 764.86047 | Y34: 0.52941277 | Z34: 0.68645993 | AA34: 0.66160415 | AB34: 5.5358252 | AC34: 0.66160415 | AD34: 1.4095341 | AE34: 5.3280246 | AF34: 2.4258495 | AG34: 0.66160415 | AH34: 0.9510975 | AI34: 0.60023935 | AJ34: 0.66160415 | AK34: 6.1205523 | AL34: 0.72622493 | AM34: 0.41161936 | AN34: 0.59255221 | AO34: 0.66160415 | AP34: 0.66160415 | AQ34: 1.3922795 | AR34: 4.9045951 | AS34: 27.960414 | AT34: 6080.0894 | AU34: 17.283874 | AV34: 5.1013891
A35: 2002 | B35: 1.868 | C35: 1.1809019 | D35: 0.67852811 | E35: 0.67852811 | F35: 1.0075294 | G35: 1 | H35: 442.02063 | I35: 1606.9991 | J35: 230.85833 | K35: 21.004979 | L35: 5.0652356 | M35: 0.68117662 | N35: 0.67852811 | O35: 0.67852811 | P35: 0.67852811 | Q35: 0.67852811 | R35: 165.45966 | S35: 58.809974 | T35: 0.67852811 | U35: 3.0397807 | V35: 0.67852811 | W35: 80.448746 | X35: 803.0261 | Y35: 0.56435472 | Z35: 0.68325139 | AA35: 0.67852811 | AB35: 6.1952469 | AC35: 0.67852811 | AD35: 1.3872581 | AE35: 5.1223793 | AF35: 2.6177427 | AG35: 0.67852811 | AH35: 0.96533121 | AI35: 0.64322675 | AJ35: 0.67852811 | AK35: 6.2473223 | AL35: 0.96703398 | AM35: 0.42808939 | AN35: 0.64159835 | AO35: 0.67852811 | AP35: 0.67852811 | AQ35: 1.8737001 | AR35: 5.3104823 | AS35: 31.188301 | AT35: 5974.0452 | AU35: 20.113135 | AV35: 6.7629257
A36: 2003 | B36: 1.88 | C36: 1.1449992 | D36: 0.65647895 | E36: 0.65647895 | F36: 1.0403696 | G36: 1 | H36: 513.42002 | I36: 2136.8147 | J36: 296.03978 | K36: 20.947524 | L36: 4.8918941 | M36: 0.65762117 | N36: 0.65647895 | O36: 0.65647895 | P36: 0.65647895 | Q36: 0.65647895 | R36: 166.56631 | S36: 56.962785 | T36: 0.65647895 | U36: 3.3818219 | V36: 0.65647895 | W36: 86.090218 | X36: 884.89592 | Y36: 0.60382071 | Z36: 0.6582911 | AA36: 0.65647895 | AB36: 8.0117421 | AC36: 0.65647895 | AD36: 1.2788015 | AE36: 5.2576485 | AF36: 2.8879609 | AG36: 0.65647895 | AH36: 0.90642443 | AI36: 0.64179236 | AJ36: 0.65647895 | AK36: 6.0047519 | AL36: 1.1145318 | AM36: 0.45481166 | AN36: 0.74258299 | AO36: 0.65647895 | AP36: 0.65647895 | AQ36: 2.2852807 | AR36: 6.1463866 | AS36: 34.591954 | AT36: 6369.2333 | AU36: 22.791376 | AV36: 5.617454
A37: 2004 | B37: 1.895 | C37: 1.0934918 | D37: 0.64650128 | E37: 0.64650128 | F37: 1.0464704 | G37: 1 | H37: 490.17387 | I37: 2113.6929 | J37: 352.18051 | K37: 20.667339 | L37: 4.8179145 | M37: 0.64737107 | N37: 0.64650128 | O37: 0.64650128 | P37: 0.64650128 | Q37: 0.64650128 | R37: 163.04504 | S37: 56.447046 | T37: 0.64650128 | U37: 3.6043413 | V37: 0.64650128 | W37: 87.006781 | X37: 921.79574 | Y37: 0.61816273 | Z37: 0.6476218 | AA37: 0.64650128 | AB37: 9.0759988 | AC37: 0.64650128 | AD37: 1.213258 | AE37: 5.4208733 | AF37: 2.9414185 | AG37: 0.64650128 | AH37: 0.8610672 | AI37: 0.645593 | AJ37: 0.64650128 | AK37: 5.9098603 | AL37: 1.1463949 | AM37: 0.43922946 | AN37: 0.80418444 | AO37: 0.64650128 | AP37: 0.64650128 | AQ37: 2.3523355 | AR37: 6.6560744 | AS37: 36.442797 | AT37: 7188.4841 | AU37: 23.171563 | AV37: 5.1947842
A38: 2005 | B38: 1.917 | C38: 1.0516366 | D38: 0.64553104 | E38: 0.64553104 | F38: 0.97287812 | G38: 1 | H38: 449.54866 | I38: 1864.0983 | J38: 383.71 | K38: 19.240175 | L38: 4.8161118 | M38: 0.64589272 | N38: 0.64553104 | O38: 0.64553104 | P38: 0.64553104 | Q38: 0.64553104 | R38: 160.28448 | S38: 50.580507 | T38: 0.64553104 | U38: 3.6040669 | V38: 0.64553104 | W38: 88.516124 | X38: 822.63695 | Y38: 0.64530556 | Z38: 0.64522023 | AA38: 0.64553104 | AB38: 8.7520847 | AC38: 0.64553104 | AD38: 1.14062 | AE38: 5.1739646 | AF38: 2.5984131 | AG38: 0.64553104 | AH38: 0.82688449 | AI38: 0.64580849 | AJ38: 0.64553104 | AK38: 6.001629 | AL38: 1.0790301 | AM38: 0.44170305 | AN38: 0.80309889 | AO38: 0.64553104 | AP38: 0.64553104 | AQ38: 1.9550559 | AR38: 6.5808466 | AS38: 35.416641 | AT38: 7793.8673 | AU38: 22.715204 | AV38: 5.1071695
A39: 2006 | B39: 1.937 | C39: 1.0591223 | D39: 0.63519318 | E39: 0.63519318 | F39: 0.90469415 | G39: 1 | H39: 422.91966 | I39: 1881.092 | J39: 407.78764 | K39: 18.021058 | L39: 4.74284 | M39: 0.63539806 | N39: 0.63519318 | O39: 0.63519318 | P39: 0.63519318 | Q39: 0.63519318 | R39: 167.79608 | S39: 55.971905 | T39: 0.63519318 | U39: 3.5537202 | V39: 0.63519318 | W39: 92.754261 | X39: 761.92999 | Y39: 0.63595602 | Z39: 0.63572492 | AA39: 0.63519318 | AB39: 8.6926663 | AC39: 0.63519318 | AD39: 1.2298632 | AE39: 5.1149399 | AF39: 2.4749171 | AG39: 0.63519318 | AH39: 0.78619719 | AI39: 0.63576268 | AJ39: 0.63519318 | AK39: 5.8845064 | AL39: 1.1392599 | AM39: 0.4334566 | AN39: 0.79754781 | AO39: 0.63519318 | AP39: 0.63519318 | AQ39: 1.734927 | AR39: 6.3591983 | AS39: 36.134505 | AT39: 7304.9929 | AU39: 21.686089 | AV39: 5.4006342
... A57: 2024 | B57: 2.113 | C57: 1.7211356 | D57: 1.0493488 | E57: 1.0493488 | F57: 1.5553115 | G57: 1 | H57: 1071.7042 | I57: 4627.7206 | J57: 585.05893 | K57: 26.369555 | L57: 7.8307152 | M57: 1.0493488 | N57: 1.0493488 | O57: 1.0493488 | P57: 1.0493488 | Q57: 1.0493488 | R57: 415.3497 | S57: 156.69199 | T57: 1.0493488 | U57: 4.2021218 | V57: 1.0493488 | W57: 171.92103 | X57: 1548.514 | Y57: 1.0493488 | Z57: 1.0493488 | AA57: 1.0493488 | AB57: 20.79056 | AC57: 1.0493488 | AD57: 1.876683 | AE57: 12.20506 | AF57: 4.5213525 | AG57: 1.0493488 | AH57: 1.0493488 | AI57: 1.0493488 | AJ57: 1.0493488 | AK57: 12.002665 | AL57: 37.260722 | AM57: 0.88866231 | AN57: 1.1357947 | AO57: 1.0493488 | AP57: 1.0493488 | AQ57: 6.1207235 | AR57: 8.174872 | AS57: 95.031124 | AT57: 18008.534 | AU57: 105.12052 | AV57: 20.817591
...

Sheet R2 CAPEX
A1: PTES (per volume) | E1: TTES (per volume) | I1: BTES (per volume) | M1: ATES (per volume)
A2: SStot | B2: SSres | C2: R2 | E2: SStot | F2: SSres | G2: R2 | I2: SStot | J2: SSres | K2: R2 | M2: SStot | N2: SSres | O2: R2
A3: =(CAPEX!I5-$A$19)^2 -> 15166.721 | B3: =(CAPEX!I5-6377.4*CAPEX!E5^(-0.425))^2 -> 10018.905 | C3: =1-SUM(B3:B17)/SUM(A3:A17) -> 0.64258252 | E3: =(CAPEX!I25-E18)^2 -> 5341977.8 | F3: =(CAPEX!I25-3189.9*CAPEX!E25^(-0.3))^2 -> 797504.15 | G3: =1-SUM(F3:F16)/SUM(E3:E16) -> 0.80730873 | I3: =(CAPEX!K69-$I$15)^2 -> 1177.4228 | J3: =(CAPEX!K69-304454*CAPEX!E69^(-0.924))^2 -> 7.4668362 | K3: =1-SUM(J3:J13)/SUM(I3:I13) -> 0.59575702 | M3: =(CAPEX!L87-$M$18)^2 -> 395.35946 | N3: =(CAPEX!L87-38344*CAPEX!F87^(-0.675))^2 -> 28.194041 | O3: =1-SUM(N3:N16)/SUM(M3:M16) -> 0.47463147
A4: =(CAPEX!I6-$A$19)^2 -> 18215.322 | B4: =(CAPEX!I6-6377.4*CAPEX!E6^(-0.425))^2 -> 0.087029473 | E4: =(CAPEX!I26-E19)^2 -> 32851289 | F4: =(CAPEX!I26-3189.9*CAPEX!E26^(-0.3))^2 -> 11815407 | I4: =(CAPEX!K70-$I$15)^2 -> 1698.8076 | J4: =(CAPEX!K70-304454*CAPEX!E70^(-0.924))^2 -> 648.33502 | M4: =(CAPEX!L89-$M$18)^2 -> 1004.0395 | N4: =(CAPEX!L89-38344*CAPEX!F89^(-0.675))^2 -> 7.7634862
A5: =(CAPEX!I7-$A$19)^2 -> 2483.2062 | B5: =(CAPEX!I7-6377.4*CAPEX!E7^(-0.425))^2 -> 146.9695 | E5: =(CAPEX!I27-E20)^2 -> 41231763 | F5: =(CAPEX!I27-3189.9*CAPEX!E27^(-0.3))^2 -> 2607742.3 | I5: =(CAPEX!K71-$I$15)^2 -> 2315.1531 | J5: =(CAPEX!K71-304454*CAPEX!E71^(-0.924))^2 -> 71.473696 | M5: =(CAPEX!L90-$M$18)^2 -> 4109.12 | N5: =(CAPEX!L90-38344*CAPEX!F90^(-0.675))^2 -> 3656.7944
A6: =(CAPEX!I8-$A$19)^2 -> 180515.69 | B6: =(CAPEX!I8-6377.4*CAPEX!E8^(-0.425))^2 -> 84217.337 | E6: =(CAPEX!I28-E21)^2 -> 35763.763 | F6: =(CAPEX!I28-3189.9*CAPEX!E28^(-0.3))^2 -> 8811.5634 | I6: =(CAPEX!K72-$I$15)^2 -> 358.85283 | J6: =(CAPEX!K72-304454*CAPEX!E72^(-0.924))^2 -> 1327.3777 | M6: =(CAPEX!L91-$M$18)^2 -> 104967.03 | N6: =(CAPEX!L91-38344*CAPEX!F91^(-0.675))^2 -> 59914.729
A7: =(CAPEX!I9-$A$19)^2 -> 1209.6128 | B7: =(CAPEX!I9-6377.4*CAPEX!E9^(-0.425))^2 -> 369.46403 | E7: =(CAPEX!I29-E22)^2 -> 16293.591 | F7: =(CAPEX!I29-3189.9*CAPEX!E29^(-0.3))^2 -> 273721.92 | I7: =(CAPEX!K73-$I$15)^2 -> 1177.4228 | J7: =(CAPEX!K73-304454*CAPEX!E73^(-0.924))^2 -> 7.4668362 | M7: =(CAPEX!L92-$M$18)^2 -> 1320.9089 | N7: =(CAPEX!L92-38344*CAPEX!F92^(-0.675))^2 -> 8.3238791
A8: =(CAPEX!I10-$A$19)^2 -> 6669.2743 | B8: =(CAPEX!I10-6377.4*CAPEX!E10^(-0.425))^2 -> 115.42862 | E8: =(CAPEX!I30-E23)^2 -> 27386.727 | F8: =(CAPEX!I30-3189.9*CAPEX!E30^(-0.3))^2 -> 25824.076 | I8: =(CAPEX!K74-$I$15)^2 -> 1973.4244 | J8: =(CAPEX!K74-304454*CAPEX!E74^(-0.924))^2 -> 20.029992 | M8: =(CAPEX!L93-$M$18)^2 -> 1338.4361 | N8: =(CAPEX!L93-38344*CAPEX!F93^(-0.675))^2 -> 34.997121
A9: =(CAPEX!I11-$A$19)^2 -> 10714.089 | B9: =(CAPEX!I11-6377.4*CAPEX!E11^(-0.425))^2 -> 159.36086 | E9: =(CAPEX!I31-E24)^2 -> 94141.336 | F9: =(CAPEX!I31-3189.9*CAPEX!E31^(-0.3))^2 -> 107.26715 | I9: =(CAPEX!K75-$I$15)^2 -> 1059.1775 | J9: =(CAPEX!K75-304454*CAPEX!E75^(-0.924))^2 -> 0.92922464 | M9: =(CAPEX!L95-$M$18)^2 -> 851.61495 | N9: =(CAPEX!L95-38344*CAPEX!F95^(-0.675))^2 -> 169.45079
A10: =(CAPEX!I12-$A$19)^2 -> 11470.716 | B10: =(CAPEX!I12-6377.4*CAPEX!E12^(-0.425))^2 -> 117.51011 | E10: =(CAPEX!I32-E25)^2 -> 72076.96 | F10: =(CAPEX!I32-3189.9*CAPEX!E32^(-0.3))^2 -> 161.8721 | I10: =(CAPEX!K76-$I$15)^2 -> 1020.8314 | J10: =(CAPEX!K76-304454*CAPEX!E76^(-0.924))^2 -> 186.51816 | M10: =(CAPEX!L96-$M$18)^2 -> 874.19577 | N10: =(CAPEX!L96-38344*CAPEX!F96^(-0.675))^2 -> 3.5130955
A11: =(CAPEX!I13-$A$19)^2 -> 688.66199 | B11: =(CAPEX!I13-6377.4*CAPEX!E13^(-0.425))^2 -> 1608.244 | E11: =(CAPEX!I33-E26)^2 -> 36773.959 | F11: =(CAPEX!I33-3189.9*CAPEX!E33^(-0.3))^2 -> 2159.8872 | I11: =(CAPEX!K77-$I$15)^2 -> 87.095047 | J11: =(CAPEX!K77-304454*CAPEX!E77^(-0.924))^2 -> 117.01279 | M11: =(CAPEX!L97-$M$18)^2 -> 1006.0654 | N11: =(CAPEX!L97-38344*CAPEX!F97^(-0.675))^2 -> 15.290997
A12: =(CAPEX!I14-$A$19)^2 -> 8551.1502 | B12: =(CAPEX!I14-6377.4*CAPEX!E14^(-0.425))^2 -> 43.40796 | E12: =(CAPEX!I34-E27)^2 -> 21614.916 | F12: =(CAPEX!I34-3189.9*CAPEX!E34^(-0.3))^2 -> 1895.3753 | I12: =(CAPEX!K78-$I$15)^2 -> 20998.247 | J12: =(CAPEX!K78-304454*CAPEX!E78^(-0.924))^2 -> 6392.512 | M12: =(CAPEX!L99-$M$18)^2 -> 1169.2347 | N12: =(CAPEX!L99-38344*CAPEX!F99^(-0.675))^2 -> 11.901093
A13: =(CAPEX!I15-$A$19)^2 -> 12229.439 | B13: =(CAPEX!I15-6377.4*CAPEX!E15^(-0.425))^2 -> 14.280368 | E13: =(CAPEX!I35-E28)^2 -> 361038.56 | F13: =(CAPEX!I35-3189.9*CAPEX!E35^(-0.3))^2 -> 603.94846 | I13: =(CAPEX!K79-$I$15)^2 -> 8778.7385 | J13: =(CAPEX!K79-304454*CAPEX!E79^(-0.924))^2 -> 7651.4034 | M13: =(CAPEX!L102-$M$18)^2 -> 1414.4853 | N13: =(CAPEX!L102-38344*CAPEX!F102^(-0.675))^2 -> 2.1613673
A14: =(CAPEX!I16-$A$19)^2 -> 15101.208 | B14: =(CAPEX!I16-6377.4*CAPEX!E16^(-0.425))^2 -> 55.8355 | E14: =(CAPEX!I36-E29)^2 -> 330965.63 | F14: =(CAPEX!I36-3189.9*CAPEX!E36^(-0.3))^2 -> 16475.71 | M14: =(CAPEX!L103-$M$18)^2 -> 1246.7053 | N14: =(CAPEX!L103-38344*CAPEX!F103^(-0.675))^2 -> 162.297
A15: =(CAPEX!I17-$A$19)^2 -> 3747.2872 | B15: =(CAPEX!I17-6377.4*CAPEX!E17^(-0.425))^2 -> 1118.1007 | E15: =(CAPEX!I37-E30)^2 -> 376565.34 | F15: =(CAPEX!I37-3189.9*CAPEX!E37^(-0.3))^2 -> 21186.75 | I15: =AVERAGE(CAPEX!K69:K79) -> 51.37056 | M15: =(CAPEX!L104-$M$18)^2 -> 1329.6979 | N15: =(CAPEX!L104-38344*CAPEX!F104^(-0.675))^2 -> 5.4996194
A16: =(CAPEX!I18-$A$19)^2 -> 26540.373 | B16: =(CAPEX!I18-6377.4*CAPEX!E18^(-0.425))^2 -> 3484.4866 | E16: =(CAPEX!I38-E31)^2 -> 41225.749 | F16: =(CAPEX!I38-3189.9*CAPEX!E38^(-0.3))^2 -> 5344.0694 | M16: =(CAPEX!L105-$M$18)^2 -> 872.85771 | N16: =(CAPEX!L105-38344*CAPEX!F105^(-0.675))^2 -> 21.379667
A17: =(CAPEX!I19-$A$19)^2 -> 461.12747 | B17: =(CAPEX!I19-6377.4*CAPEX!E19^(-0.425))^2 -> 10675.276
E18: =AVERAGE(CAPEX!I25:I38) -> 1373.3273 | M18: =AVERAGE(CAPEX!L87:L105) -> 38.738661
A19: =AVERAGE(CAPEX!I5:I19) -> 150.30462
I25: BTES (per energy) | M25: ATES (per energy)
I26: SStot | J26: SSres | K26: R2 | M26: SStot | N26: SSres | O26: R2
I27: =(CAPEX!M69-$I$40)^2 -> 585774.01 | J27: =(CAPEX!M69-953771*CAPEX!F69^(-1.057))^2 -> 16823.876 | K27: =1-SUM(J27:J38)/SUM(I27:I38) -> 0.32369191 | M27: =(CAPEX!M87-$M$40)^2 -> 88371.967 | N27: =(CAPEX!M87-81779*CAPEX!G87^(-0.63))^2 -> 4596.6124 | O27: =1-SUM(N27:N38)/SUM(M27:M38) -> 0.50023078
I28: =(CAPEX!M70-$I$40)^2 -> 2309415.9 | J28: =(CAPEX!M70-953771*CAPEX!F70^(-1.057))^2 -> 193293.98 | M28: =(CAPEX!M89-$M$40)^2 -> 225629 | N28: =(CAPEX!M89-81779*CAPEX!G89^(-0.63))^2 -> 6481.9159
I29: =(CAPEX!M71-$I$40)^2 -> 2292007.8 | J29: =(CAPEX!M71-953771*CAPEX!F71^(-1.057))^2 -> 169971.38 | M29: =(CAPEX!M90-$M$40)^2 -> 1117651.6 | N29: =(CAPEX!M90-81779*CAPEX!G90^(-0.63))^2 -> 829396.75
I30: =(CAPEX!M72-$I$40)^2 -> 11858271 | J30: =(CAPEX!M72-953771*CAPEX!F72^(-1.057))^2 -> 6083358.8 | M30: =(CAPEX!M91-$M$40)^2 -> 5593769.7 | N30: =(CAPEX!M91-81779*CAPEX!G91^(-0.63))^2 -> 2722652.7
I31: =(CAPEX!M73-$I$40)^2 -> 112002.49 | J31: =(CAPEX!M73-953771*CAPEX!F73^(-1.057))^2 -> 50096.091 | M31: =(CAPEX!M92-$M$40)^2 -> 250569.73 | N31: =(CAPEX!M92-81779*CAPEX!G92^(-0.63))^2 -> 17187.049
I32: =(CAPEX!M74-$I$40)^2 -> 1147931.9 | J32: =(CAPEX!M74-953771*CAPEX!F74^(-1.057))^2 -> 209036.22 | M32: =(CAPEX!M93-$M$40)^2 -> 303768.54 | N32: =(CAPEX!M93-81779*CAPEX!G93^(-0.63))^2 -> 85448.062
I33: =(CAPEX!M75-$I$40)^2 -> 504133.25 | J33: =(CAPEX!M75-953771*CAPEX!F75^(-1.057))^2 -> 878.81478 | M33: =(CAPEX!M96-$M$40)^2 -> 587104.35 | N33: =(CAPEX!M96-81779*CAPEX!G96^(-0.63))^2 -> 634532.66
I34: =(CAPEX!M76-$I$40)^2 -> 1657781.9 | J34: =(CAPEX!M76-953771*CAPEX!F76^(-1.057))^2 -> 82622.18 | M34: =(CAPEX!M97-$M$40)^2 -> 91289.922 | N34: =(CAPEX!M97-81779*CAPEX!G97^(-0.63))^2 -> 59571.137
I35: =(CAPEX!M77-$I$40)^2 -> 149374.22 | J35: =(CAPEX!M77-953771*CAPEX!F77^(-1.057))^2 -> 26915.101 | M35: =(CAPEX!M102-$M$40)^2 -> 395415.89 | N35: =(CAPEX!M102-81779*CAPEX!G102^(-0.63))^2 -> 5373.8382
I36: =(CAPEX!M78-$I$40)^2 -> 2853949.4 | J36: =(CAPEX!M78-953771*CAPEX!F78^(-1.057))^2 -> 1006995.8 | M36: =(CAPEX!M103-$M$40)^2 -> 265479.39 | N36: =(CAPEX!M103-81779*CAPEX!G103^(-0.63))^2 -> 288289.34
I37: =(CAPEX!M79-$I$40)^2 -> 660724.04 | J37: =(CAPEX!M79-953771*CAPEX!F79^(-1.057))^2 -> 2072035.4 | M37: =(CAPEX!M104-$M$40)^2 -> 181447.91 | N37: =(CAPEX!M104-81779*CAPEX!G104^(-0.63))^2 -> 8656.3372
I38: =(CAPEX!M81-$I$40)^2 -> 2700504.9 | J38: =(CAPEX!M81-953771*CAPEX!F81^(-1.057))^2 -> 8234583.7 | M38: =(CAPEX!M105-$M$40)^2 -> 242414.29 | N38: =(CAPEX!M105-81779*CAPEX!G105^(-0.63))^2 -> 7113.5523
I40: =AVERAGE(CAPEX!M69:M81) -> 1694.7446 | M40: =AVERAGE(CAPEX!M87:M105) -> 705.79952
I42: BTES (energy density u) | M42: ATES (energy density u)
I43: u [MWh/m3] | J43: SSres | K43: R2 | M43: u [MWh/m3] | N43: SSres | O43: R2
I44: 0.015 | J44: =(CAPEX!M69-304454/$I$44^(-0.924+1)*CAPEX!F69^(-0.924))^2 -> 27406.385 | K44: =1-SUM(J44:J55)/SUM(I27:I38) -> 0.28399177 | M44: 0.03 | N44: =(CAPEX!M87-38344/$M$44^(-0.675+1)*CAPEX!G87^(-0.675))^2 -> 5032.7702 | O44: =1-SUM(N44:N55)/SUM(M27:M38) -> 0.55595331
J45: =(CAPEX!M70-304454/$I$44^(-0.924+1)*CAPEX!F70^(-0.924))^2 -> 255510.81 | N45: =(CAPEX!M89-38344/$M$44^(-0.675+1)*CAPEX!G89^(-0.675))^2 -> 8163.6787
J46: =(CAPEX!M71-304454/$I$44^(-0.924+1)*CAPEX!F71^(-0.924))^2 -> 229205.94 | N46: =(CAPEX!M90-38344/$M$44^(-0.675+1)*CAPEX!G90^(-0.675))^2 -> 742054.57
J47: =(CAPEX!M72-304454/$I$44^(-0.924+1)*CAPEX!F72^(-0.924))^2 -> 7180475.4 | N47: =(CAPEX!M91-38344/$M$44^(-0.675+1)*CAPEX!G91^(-0.675))^2 -> 2286120.6
...
